[2025-07-16T18:18:57.887+0000] {local_task_job_runner.py:120} INFO - ::group::Pre task execution logs
[2025-07-16T18:18:58.002+0000] {taskinstance.py:2076} INFO - Dependencies all met for dep_context=non-requeueable deps ti=<TaskInstance: etl_pipeline.extract scheduled__2025-07-15T00:00:00+00:00 [queued]>
[2025-07-16T18:18:58.009+0000] {taskinstance.py:2076} INFO - Dependencies all met for dep_context=requeueable deps ti=<TaskInstance: etl_pipeline.extract scheduled__2025-07-15T00:00:00+00:00 [queued]>
[2025-07-16T18:18:58.010+0000] {taskinstance.py:2306} INFO - Starting attempt 2 of 2
[2025-07-16T18:18:58.020+0000] {taskinstance.py:2330} INFO - Executing <Task(_PythonDecoratedOperator): extract> on 2025-07-15 00:00:00+00:00
[2025-07-16T18:18:58.027+0000] {standard_task_runner.py:63} INFO - Started process 70 to run task
[2025-07-16T18:18:58.030+0000] {standard_task_runner.py:90} INFO - Running: ['airflow', 'tasks', 'run', 'etl_pipeline', 'extract', 'scheduled__2025-07-15T00:00:00+00:00', '--job-id', '5', '--raw', '--subdir', 'DAGS_FOLDER/etl_dag.py', '--cfg-path', '/tmp/tmp24wma0s7']
[2025-07-16T18:18:58.032+0000] {standard_task_runner.py:91} INFO - Job 5: Subtask extract
[2025-07-16T18:18:58.077+0000] {task_command.py:426} INFO - Running <TaskInstance: etl_pipeline.extract scheduled__2025-07-15T00:00:00+00:00 [running]> on host 8e88189d29cb
[2025-07-16T18:18:58.148+0000] {taskinstance.py:2648} INFO - Exporting env vars: AIRFLOW_CTX_DAG_OWNER='airflow' AIRFLOW_CTX_DAG_ID='etl_pipeline' AIRFLOW_CTX_TASK_ID='extract' AIRFLOW_CTX_EXECUTION_DATE='2025-07-15T00:00:00+00:00' AIRFLOW_CTX_TRY_NUMBER='2' AIRFLOW_CTX_DAG_RUN_ID='scheduled__2025-07-15T00:00:00+00:00'
[2025-07-16T18:18:58.150+0000] {taskinstance.py:430} INFO - ::endgroup::
[2025-07-16T18:18:58.152+0000] {taskinstance.py:441} INFO - ::group::Post task execution logs
[2025-07-16T18:18:58.152+0000] {taskinstance.py:2905} ERROR - Task failed with exception
Traceback (most recent call last):
  File "/home/airflow/.local/lib/python3.11/site-packages/airflow/models/taskinstance.py", line 465, in _execute_task
    result = _execute_callable(context=context, **execute_callable_kwargs)
             ^^^^^^^^^^^^^^^^^^^^^^^^^^^^^^^^^^^^^^^^^^^^^^^^^^^^^^^^^^^^^
  File "/home/airflow/.local/lib/python3.11/site-packages/airflow/models/taskinstance.py", line 432, in _execute_callable
    return execute_callable(context=context, **execute_callable_kwargs)
           ^^^^^^^^^^^^^^^^^^^^^^^^^^^^^^^^^^^^^^^^^^^^^^^^^^^^^^^^^^^^
  File "/home/airflow/.local/lib/python3.11/site-packages/airflow/models/baseoperator.py", line 400, in wrapper
    return func(self, *args, **kwargs)
           ^^^^^^^^^^^^^^^^^^^^^^^^^^^
  File "/home/airflow/.local/lib/python3.11/site-packages/airflow/decorators/base.py", line 265, in execute
    return_value = super().execute(context)
                   ^^^^^^^^^^^^^^^^^^^^^^^^
  File "/home/airflow/.local/lib/python3.11/site-packages/airflow/models/baseoperator.py", line 400, in wrapper
    return func(self, *args, **kwargs)
           ^^^^^^^^^^^^^^^^^^^^^^^^^^^
  File "/home/airflow/.local/lib/python3.11/site-packages/airflow/operators/python.py", line 235, in execute
    return_value = self.execute_callable()
                   ^^^^^^^^^^^^^^^^^^^^^^^
  File "/home/airflow/.local/lib/python3.11/site-packages/airflow/operators/python.py", line 252, in execute_callable
    return self.python_callable(*self.op_args, **self.op_kwargs)
           ^^^^^^^^^^^^^^^^^^^^^^^^^^^^^^^^^^^^^^^^^^^^^^^^^^^^^
  File "/opt/airflow/dags/etl_dag.py", line 25, in extract
    return _extract().to_dict(orient="records")
           ^^^^^^^^^^
  File "/opt/airflow/app/pipeline.py", line 19, in extract
    return pd.read_csv(CSV_PATH)
           ^^^^^^^^^^^^^^^^^^^^^
  File "/home/airflow/.local/lib/python3.11/site-packages/pandas/io/parsers/readers.py", line 948, in read_csv
    return _read(filepath_or_buffer, kwds)
           ^^^^^^^^^^^^^^^^^^^^^^^^^^^^^^^
  File "/home/airflow/.local/lib/python3.11/site-packages/pandas/io/parsers/readers.py", line 611, in _read
    parser = TextFileReader(filepath_or_buffer, **kwds)
             ^^^^^^^^^^^^^^^^^^^^^^^^^^^^^^^^^^^^^^^^^^
  File "/home/airflow/.local/lib/python3.11/site-packages/pandas/io/parsers/readers.py", line 1448, in __init__
    self._engine = self._make_engine(f, self.engine)
                   ^^^^^^^^^^^^^^^^^^^^^^^^^^^^^^^^^
  File "/home/airflow/.local/lib/python3.11/site-packages/pandas/io/parsers/readers.py", line 1705, in _make_engine
    self.handles = get_handle(
                   ^^^^^^^^^^^
  File "/home/airflow/.local/lib/python3.11/site-packages/pandas/io/common.py", line 863, in get_handle
    handle = open(
             ^^^^^
FileNotFoundError: [Errno 2] No such file or directory: '/app/data/input.csv'
[2025-07-16T18:18:58.167+0000] {taskinstance.py:1206} INFO - Marking task as FAILED. dag_id=etl_pipeline, task_id=extract, run_id=scheduled__2025-07-15T00:00:00+00:00, execution_date=20250715T000000, start_date=20250716T181858, end_date=20250716T181858
[2025-07-16T18:18:58.178+0000] {standard_task_runner.py:110} ERROR - Failed to execute job 5 for task extract ([Errno 2] No such file or directory: '/app/data/input.csv'; 70)
[2025-07-16T18:18:58.217+0000] {local_task_job_runner.py:240} INFO - Task exited with return code 1
[2025-07-16T18:18:58.236+0000] {taskinstance.py:3498} INFO - 0 downstream tasks scheduled from follow-on schedule check
[2025-07-16T18:18:58.240+0000] {local_task_job_runner.py:222} INFO - ::endgroup::
[2025-07-16T20:37:37.348+0000] {local_task_job_runner.py:120} INFO - ::group::Pre task execution logs
[2025-07-16T20:37:37.442+0000] {taskinstance.py:2076} INFO - Dependencies all met for dep_context=non-requeueable deps ti=<TaskInstance: etl_pipeline.extract scheduled__2025-07-15T00:00:00+00:00 [queued]>
[2025-07-16T20:37:37.450+0000] {taskinstance.py:2076} INFO - Dependencies all met for dep_context=requeueable deps ti=<TaskInstance: etl_pipeline.extract scheduled__2025-07-15T00:00:00+00:00 [queued]>
[2025-07-16T20:37:37.451+0000] {taskinstance.py:2306} INFO - Starting attempt 2 of 2
[2025-07-16T20:37:37.460+0000] {taskinstance.py:2330} INFO - Executing <Task(_PythonDecoratedOperator): extract> on 2025-07-15 00:00:00+00:00
[2025-07-16T20:37:37.466+0000] {standard_task_runner.py:63} INFO - Started process 125 to run task
[2025-07-16T20:37:37.469+0000] {standard_task_runner.py:90} INFO - Running: ['airflow', 'tasks', 'run', 'etl_pipeline', 'extract', 'scheduled__2025-07-15T00:00:00+00:00', '--job-id', '6', '--raw', '--subdir', 'DAGS_FOLDER/etl_dag.py', '--cfg-path', '/tmp/tmpmffkfjdd']
[2025-07-16T20:37:37.471+0000] {standard_task_runner.py:91} INFO - Job 6: Subtask extract
[2025-07-16T20:37:37.512+0000] {task_command.py:426} INFO - Running <TaskInstance: etl_pipeline.extract scheduled__2025-07-15T00:00:00+00:00 [running]> on host 105b7bd1729a
[2025-07-16T20:37:37.598+0000] {taskinstance.py:2648} INFO - Exporting env vars: AIRFLOW_CTX_DAG_OWNER='airflow' AIRFLOW_CTX_DAG_ID='etl_pipeline' AIRFLOW_CTX_TASK_ID='extract' AIRFLOW_CTX_EXECUTION_DATE='2025-07-15T00:00:00+00:00' AIRFLOW_CTX_TRY_NUMBER='2' AIRFLOW_CTX_DAG_RUN_ID='scheduled__2025-07-15T00:00:00+00:00'
[2025-07-16T20:37:37.599+0000] {taskinstance.py:430} INFO - ::endgroup::
[2025-07-16T20:37:37.601+0000] {taskinstance.py:441} INFO - ::group::Post task execution logs
[2025-07-16T20:37:37.601+0000] {taskinstance.py:2905} ERROR - Task failed with exception
Traceback (most recent call last):
  File "/home/airflow/.local/lib/python3.11/site-packages/airflow/models/taskinstance.py", line 465, in _execute_task
    result = _execute_callable(context=context, **execute_callable_kwargs)
             ^^^^^^^^^^^^^^^^^^^^^^^^^^^^^^^^^^^^^^^^^^^^^^^^^^^^^^^^^^^^^
  File "/home/airflow/.local/lib/python3.11/site-packages/airflow/models/taskinstance.py", line 432, in _execute_callable
    return execute_callable(context=context, **execute_callable_kwargs)
           ^^^^^^^^^^^^^^^^^^^^^^^^^^^^^^^^^^^^^^^^^^^^^^^^^^^^^^^^^^^^
  File "/home/airflow/.local/lib/python3.11/site-packages/airflow/models/baseoperator.py", line 400, in wrapper
    return func(self, *args, **kwargs)
           ^^^^^^^^^^^^^^^^^^^^^^^^^^^
  File "/home/airflow/.local/lib/python3.11/site-packages/airflow/decorators/base.py", line 265, in execute
    return_value = super().execute(context)
                   ^^^^^^^^^^^^^^^^^^^^^^^^
  File "/home/airflow/.local/lib/python3.11/site-packages/airflow/models/baseoperator.py", line 400, in wrapper
    return func(self, *args, **kwargs)
           ^^^^^^^^^^^^^^^^^^^^^^^^^^^
  File "/home/airflow/.local/lib/python3.11/site-packages/airflow/operators/python.py", line 235, in execute
    return_value = self.execute_callable()
                   ^^^^^^^^^^^^^^^^^^^^^^^
  File "/home/airflow/.local/lib/python3.11/site-packages/airflow/operators/python.py", line 252, in execute_callable
    return self.python_callable(*self.op_args, **self.op_kwargs)
           ^^^^^^^^^^^^^^^^^^^^^^^^^^^^^^^^^^^^^^^^^^^^^^^^^^^^^
  File "/opt/airflow/dags/etl_dag.py", line 25, in extract
    return _extract().to_dict(orient="records")
           ^^^^^^^^^^
  File "/opt/airflow/app/pipeline.py", line 19, in extract
    return pd.read_csv(CSV_PATH)
           ^^^^^^^^^^^^^^^^^^^^^
  File "/home/airflow/.local/lib/python3.11/site-packages/pandas/io/parsers/readers.py", line 948, in read_csv
    return _read(filepath_or_buffer, kwds)
           ^^^^^^^^^^^^^^^^^^^^^^^^^^^^^^^
  File "/home/airflow/.local/lib/python3.11/site-packages/pandas/io/parsers/readers.py", line 611, in _read
    parser = TextFileReader(filepath_or_buffer, **kwds)
             ^^^^^^^^^^^^^^^^^^^^^^^^^^^^^^^^^^^^^^^^^^
  File "/home/airflow/.local/lib/python3.11/site-packages/pandas/io/parsers/readers.py", line 1448, in __init__
    self._engine = self._make_engine(f, self.engine)
                   ^^^^^^^^^^^^^^^^^^^^^^^^^^^^^^^^^
  File "/home/airflow/.local/lib/python3.11/site-packages/pandas/io/parsers/readers.py", line 1705, in _make_engine
    self.handles = get_handle(
                   ^^^^^^^^^^^
  File "/home/airflow/.local/lib/python3.11/site-packages/pandas/io/common.py", line 863, in get_handle
    handle = open(
             ^^^^^
FileNotFoundError: [Errno 2] No such file or directory: '/app/data/input.csv'
[2025-07-16T20:37:37.614+0000] {taskinstance.py:1206} INFO - Marking task as FAILED. dag_id=etl_pipeline, task_id=extract, run_id=scheduled__2025-07-15T00:00:00+00:00, execution_date=20250715T000000, start_date=20250716T203737, end_date=20250716T203737
[2025-07-16T20:37:37.623+0000] {standard_task_runner.py:110} ERROR - Failed to execute job 6 for task extract ([Errno 2] No such file or directory: '/app/data/input.csv'; 125)
[2025-07-16T20:37:37.628+0000] {local_task_job_runner.py:240} INFO - Task exited with return code 1
[2025-07-16T20:37:37.649+0000] {taskinstance.py:3498} INFO - 0 downstream tasks scheduled from follow-on schedule check
[2025-07-16T20:37:37.654+0000] {local_task_job_runner.py:222} INFO - ::endgroup::
[2025-07-16T20:55:14.396+0000] {local_task_job_runner.py:120} INFO - ::group::Pre task execution logs
[2025-07-16T20:55:14.488+0000] {taskinstance.py:2076} INFO - Dependencies all met for dep_context=non-requeueable deps ti=<TaskInstance: etl_pipeline.extract scheduled__2025-07-15T00:00:00+00:00 [queued]>
[2025-07-16T20:55:14.494+0000] {taskinstance.py:2076} INFO - Dependencies all met for dep_context=requeueable deps ti=<TaskInstance: etl_pipeline.extract scheduled__2025-07-15T00:00:00+00:00 [queued]>
[2025-07-16T20:55:14.495+0000] {taskinstance.py:2306} INFO - Starting attempt 2 of 2
[2025-07-16T20:55:14.506+0000] {taskinstance.py:2330} INFO - Executing <Task(_PythonDecoratedOperator): extract> on 2025-07-15 00:00:00+00:00
[2025-07-16T20:55:14.512+0000] {standard_task_runner.py:63} INFO - Started process 282 to run task
[2025-07-16T20:55:14.514+0000] {standard_task_runner.py:90} INFO - Running: ['airflow', 'tasks', 'run', 'etl_pipeline', 'extract', 'scheduled__2025-07-15T00:00:00+00:00', '--job-id', '16', '--raw', '--subdir', 'DAGS_FOLDER/etl_dag.py', '--cfg-path', '/tmp/tmp9m_3xydb']
[2025-07-16T20:55:14.517+0000] {standard_task_runner.py:91} INFO - Job 16: Subtask extract
[2025-07-16T20:55:14.562+0000] {task_command.py:426} INFO - Running <TaskInstance: etl_pipeline.extract scheduled__2025-07-15T00:00:00+00:00 [running]> on host 105b7bd1729a
[2025-07-16T20:55:14.631+0000] {taskinstance.py:2648} INFO - Exporting env vars: AIRFLOW_CTX_DAG_OWNER='airflow' AIRFLOW_CTX_DAG_ID='etl_pipeline' AIRFLOW_CTX_TASK_ID='extract' AIRFLOW_CTX_EXECUTION_DATE='2025-07-15T00:00:00+00:00' AIRFLOW_CTX_TRY_NUMBER='2' AIRFLOW_CTX_DAG_RUN_ID='scheduled__2025-07-15T00:00:00+00:00'
[2025-07-16T20:55:14.632+0000] {taskinstance.py:430} INFO - ::endgroup::
[2025-07-16T20:55:14.634+0000] {taskinstance.py:441} INFO - ::group::Post task execution logs
[2025-07-16T20:55:14.635+0000] {taskinstance.py:2905} ERROR - Task failed with exception
Traceback (most recent call last):
  File "/home/airflow/.local/lib/python3.11/site-packages/airflow/models/taskinstance.py", line 465, in _execute_task
    result = _execute_callable(context=context, **execute_callable_kwargs)
             ^^^^^^^^^^^^^^^^^^^^^^^^^^^^^^^^^^^^^^^^^^^^^^^^^^^^^^^^^^^^^
  File "/home/airflow/.local/lib/python3.11/site-packages/airflow/models/taskinstance.py", line 432, in _execute_callable
    return execute_callable(context=context, **execute_callable_kwargs)
           ^^^^^^^^^^^^^^^^^^^^^^^^^^^^^^^^^^^^^^^^^^^^^^^^^^^^^^^^^^^^
  File "/home/airflow/.local/lib/python3.11/site-packages/airflow/models/baseoperator.py", line 400, in wrapper
    return func(self, *args, **kwargs)
           ^^^^^^^^^^^^^^^^^^^^^^^^^^^
  File "/home/airflow/.local/lib/python3.11/site-packages/airflow/decorators/base.py", line 265, in execute
    return_value = super().execute(context)
                   ^^^^^^^^^^^^^^^^^^^^^^^^
  File "/home/airflow/.local/lib/python3.11/site-packages/airflow/models/baseoperator.py", line 400, in wrapper
    return func(self, *args, **kwargs)
           ^^^^^^^^^^^^^^^^^^^^^^^^^^^
  File "/home/airflow/.local/lib/python3.11/site-packages/airflow/operators/python.py", line 235, in execute
    return_value = self.execute_callable()
                   ^^^^^^^^^^^^^^^^^^^^^^^
  File "/home/airflow/.local/lib/python3.11/site-packages/airflow/operators/python.py", line 252, in execute_callable
    return self.python_callable(*self.op_args, **self.op_kwargs)
           ^^^^^^^^^^^^^^^^^^^^^^^^^^^^^^^^^^^^^^^^^^^^^^^^^^^^^
  File "/opt/airflow/dags/etl_dag.py", line 25, in extract
    return _extract().to_dict(orient="records")
           ^^^^^^^^^^
  File "/opt/airflow/app/pipeline.py", line 19, in extract
    return pd.read_csv(CSV_PATH)
           ^^^^^^^^^^^^^^^^^^^^^
  File "/home/airflow/.local/lib/python3.11/site-packages/pandas/io/parsers/readers.py", line 948, in read_csv
    return _read(filepath_or_buffer, kwds)
           ^^^^^^^^^^^^^^^^^^^^^^^^^^^^^^^
  File "/home/airflow/.local/lib/python3.11/site-packages/pandas/io/parsers/readers.py", line 611, in _read
    parser = TextFileReader(filepath_or_buffer, **kwds)
             ^^^^^^^^^^^^^^^^^^^^^^^^^^^^^^^^^^^^^^^^^^
  File "/home/airflow/.local/lib/python3.11/site-packages/pandas/io/parsers/readers.py", line 1448, in __init__
    self._engine = self._make_engine(f, self.engine)
                   ^^^^^^^^^^^^^^^^^^^^^^^^^^^^^^^^^
  File "/home/airflow/.local/lib/python3.11/site-packages/pandas/io/parsers/readers.py", line 1705, in _make_engine
    self.handles = get_handle(
                   ^^^^^^^^^^^
  File "/home/airflow/.local/lib/python3.11/site-packages/pandas/io/common.py", line 863, in get_handle
    handle = open(
             ^^^^^
FileNotFoundError: [Errno 2] No such file or directory: '/app/data/input.csv'
[2025-07-16T20:55:14.645+0000] {taskinstance.py:1206} INFO - Marking task as FAILED. dag_id=etl_pipeline, task_id=extract, run_id=scheduled__2025-07-15T00:00:00+00:00, execution_date=20250715T000000, start_date=20250716T205514, end_date=20250716T205514
[2025-07-16T20:55:14.653+0000] {standard_task_runner.py:110} ERROR - Failed to execute job 16 for task extract ([Errno 2] No such file or directory: '/app/data/input.csv'; 282)
[2025-07-16T20:55:14.659+0000] {local_task_job_runner.py:240} INFO - Task exited with return code 1
[2025-07-16T20:55:14.676+0000] {taskinstance.py:3498} INFO - 0 downstream tasks scheduled from follow-on schedule check
[2025-07-16T20:55:14.680+0000] {local_task_job_runner.py:222} INFO - ::endgroup::
[2025-07-16T21:12:40.307+0000] {local_task_job_runner.py:120} INFO - ::group::Pre task execution logs
[2025-07-16T21:12:40.510+0000] {taskinstance.py:2076} INFO - Dependencies all met for dep_context=non-requeueable deps ti=<TaskInstance: etl_pipeline.extract scheduled__2025-07-15T00:00:00+00:00 [queued]>
[2025-07-16T21:12:40.521+0000] {taskinstance.py:2076} INFO - Dependencies all met for dep_context=requeueable deps ti=<TaskInstance: etl_pipeline.extract scheduled__2025-07-15T00:00:00+00:00 [queued]>
[2025-07-16T21:12:40.521+0000] {taskinstance.py:2306} INFO - Starting attempt 2 of 2
[2025-07-16T21:12:40.532+0000] {taskinstance.py:2330} INFO - Executing <Task(_PythonDecoratedOperator): extract> on 2025-07-15 00:00:00+00:00
[2025-07-16T21:12:40.538+0000] {standard_task_runner.py:63} INFO - Started process 147 to run task
[2025-07-16T21:12:40.543+0000] {standard_task_runner.py:90} INFO - Running: ['airflow', 'tasks', 'run', 'etl_pipeline', 'extract', 'scheduled__2025-07-15T00:00:00+00:00', '--job-id', '5', '--raw', '--subdir', 'DAGS_FOLDER/etl_dag.py', '--cfg-path', '/tmp/tmpodpoglcg']
[2025-07-16T21:12:40.547+0000] {standard_task_runner.py:91} INFO - Job 5: Subtask extract
[2025-07-16T21:12:40.627+0000] {task_command.py:426} INFO - Running <TaskInstance: etl_pipeline.extract scheduled__2025-07-15T00:00:00+00:00 [running]> on host 133ed89fe8ce
[2025-07-16T21:12:40.735+0000] {taskinstance.py:2648} INFO - Exporting env vars: AIRFLOW_CTX_DAG_OWNER='airflow' AIRFLOW_CTX_DAG_ID='etl_pipeline' AIRFLOW_CTX_TASK_ID='extract' AIRFLOW_CTX_EXECUTION_DATE='2025-07-15T00:00:00+00:00' AIRFLOW_CTX_TRY_NUMBER='2' AIRFLOW_CTX_DAG_RUN_ID='scheduled__2025-07-15T00:00:00+00:00'
[2025-07-16T21:12:40.736+0000] {taskinstance.py:430} INFO - ::endgroup::
[2025-07-16T21:12:40.755+0000] {taskinstance.py:441} INFO - ::group::Post task execution logs
[2025-07-16T21:12:40.756+0000] {taskinstance.py:2905} ERROR - Task failed with exception
Traceback (most recent call last):
  File "/home/airflow/.local/lib/python3.11/site-packages/airflow/models/taskinstance.py", line 465, in _execute_task
    result = _execute_callable(context=context, **execute_callable_kwargs)
             ^^^^^^^^^^^^^^^^^^^^^^^^^^^^^^^^^^^^^^^^^^^^^^^^^^^^^^^^^^^^^
  File "/home/airflow/.local/lib/python3.11/site-packages/airflow/models/taskinstance.py", line 432, in _execute_callable
    return execute_callable(context=context, **execute_callable_kwargs)
           ^^^^^^^^^^^^^^^^^^^^^^^^^^^^^^^^^^^^^^^^^^^^^^^^^^^^^^^^^^^^
  File "/home/airflow/.local/lib/python3.11/site-packages/airflow/models/baseoperator.py", line 400, in wrapper
    return func(self, *args, **kwargs)
           ^^^^^^^^^^^^^^^^^^^^^^^^^^^
  File "/home/airflow/.local/lib/python3.11/site-packages/airflow/decorators/base.py", line 265, in execute
    return_value = super().execute(context)
                   ^^^^^^^^^^^^^^^^^^^^^^^^
  File "/home/airflow/.local/lib/python3.11/site-packages/airflow/models/baseoperator.py", line 400, in wrapper
    return func(self, *args, **kwargs)
           ^^^^^^^^^^^^^^^^^^^^^^^^^^^
  File "/home/airflow/.local/lib/python3.11/site-packages/airflow/operators/python.py", line 235, in execute
    return_value = self.execute_callable()
                   ^^^^^^^^^^^^^^^^^^^^^^^
  File "/home/airflow/.local/lib/python3.11/site-packages/airflow/operators/python.py", line 252, in execute_callable
    return self.python_callable(*self.op_args, **self.op_kwargs)
           ^^^^^^^^^^^^^^^^^^^^^^^^^^^^^^^^^^^^^^^^^^^^^^^^^^^^^
  File "/opt/airflow/dags/etl_dag.py", line 25, in extract
    return _extract().to_dict(orient="records")
           ^^^^^^^^^^
  File "/opt/airflow/app/pipeline.py", line 19, in extract
    return pd.read_csv(CSV_PATH)
           ^^^^^^^^^^^^^^^^^^^^^
  File "/home/airflow/.local/lib/python3.11/site-packages/pandas/io/parsers/readers.py", line 948, in read_csv
    return _read(filepath_or_buffer, kwds)
           ^^^^^^^^^^^^^^^^^^^^^^^^^^^^^^^
  File "/home/airflow/.local/lib/python3.11/site-packages/pandas/io/parsers/readers.py", line 611, in _read
    parser = TextFileReader(filepath_or_buffer, **kwds)
             ^^^^^^^^^^^^^^^^^^^^^^^^^^^^^^^^^^^^^^^^^^
  File "/home/airflow/.local/lib/python3.11/site-packages/pandas/io/parsers/readers.py", line 1448, in __init__
    self._engine = self._make_engine(f, self.engine)
                   ^^^^^^^^^^^^^^^^^^^^^^^^^^^^^^^^^
  File "/home/airflow/.local/lib/python3.11/site-packages/pandas/io/parsers/readers.py", line 1705, in _make_engine
    self.handles = get_handle(
                   ^^^^^^^^^^^
  File "/home/airflow/.local/lib/python3.11/site-packages/pandas/io/common.py", line 863, in get_handle
    handle = open(
             ^^^^^
FileNotFoundError: [Errno 2] No such file or directory: '/app/data/input.csv'
[2025-07-16T21:12:40.779+0000] {taskinstance.py:1206} INFO - Marking task as FAILED. dag_id=etl_pipeline, task_id=extract, run_id=scheduled__2025-07-15T00:00:00+00:00, execution_date=20250715T000000, start_date=20250716T211240, end_date=20250716T211240
[2025-07-16T21:12:40.794+0000] {standard_task_runner.py:110} ERROR - Failed to execute job 5 for task extract ([Errno 2] No such file or directory: '/app/data/input.csv'; 147)
[2025-07-16T21:12:40.802+0000] {local_task_job_runner.py:240} INFO - Task exited with return code 1
[2025-07-16T21:12:40.822+0000] {taskinstance.py:3498} INFO - 0 downstream tasks scheduled from follow-on schedule check
[2025-07-16T21:12:40.825+0000] {local_task_job_runner.py:222} INFO - ::endgroup::
