[2025-06-22T15:19:51.320+0000] {local_task_job_runner.py:120} INFO - ::group::Pre task execution logs
[2025-06-22T15:19:51.412+0000] {taskinstance.py:2076} INFO - Dependencies all met for dep_context=non-requeueable deps ti=<TaskInstance: etl_pipeline.extract scheduled__2025-06-21T00:00:00+00:00 [queued]>
[2025-06-22T15:19:51.420+0000] {taskinstance.py:2076} INFO - Dependencies all met for dep_context=requeueable deps ti=<TaskInstance: etl_pipeline.extract scheduled__2025-06-21T00:00:00+00:00 [queued]>
[2025-06-22T15:19:51.420+0000] {taskinstance.py:2306} INFO - Starting attempt 1 of 2
[2025-06-22T15:19:51.432+0000] {taskinstance.py:2330} INFO - Executing <Task(_PythonDecoratedOperator): extract> on 2025-06-21 00:00:00+00:00
[2025-06-22T15:19:51.442+0000] {standard_task_runner.py:63} INFO - Started process 72 to run task
[2025-06-22T15:19:51.444+0000] {standard_task_runner.py:90} INFO - Running: ['airflow', 'tasks', 'run', 'etl_pipeline', 'extract', 'scheduled__2025-06-21T00:00:00+00:00', '--job-id', '4', '--raw', '--subdir', 'DAGS_FOLDER/etl_dag.py', '--cfg-path', '/tmp/tmpoba0gf7n']
[2025-06-22T15:19:51.446+0000] {standard_task_runner.py:91} INFO - Job 4: Subtask extract
[2025-06-22T15:19:51.518+0000] {task_command.py:426} INFO - Running <TaskInstance: etl_pipeline.extract scheduled__2025-06-21T00:00:00+00:00 [running]> on host ecff408c7856
[2025-06-22T15:19:51.628+0000] {taskinstance.py:2648} INFO - Exporting env vars: AIRFLOW_CTX_DAG_OWNER='airflow' AIRFLOW_CTX_DAG_ID='etl_pipeline' AIRFLOW_CTX_TASK_ID='extract' AIRFLOW_CTX_EXECUTION_DATE='2025-06-21T00:00:00+00:00' AIRFLOW_CTX_TRY_NUMBER='1' AIRFLOW_CTX_DAG_RUN_ID='scheduled__2025-06-21T00:00:00+00:00'
[2025-06-22T15:19:51.629+0000] {taskinstance.py:430} INFO - ::endgroup::
[2025-06-22T15:19:51.631+0000] {taskinstance.py:441} INFO - ::group::Post task execution logs
[2025-06-22T15:19:51.631+0000] {taskinstance.py:2905} ERROR - Task failed with exception
Traceback (most recent call last):
  File "/home/airflow/.local/lib/python3.11/site-packages/airflow/models/taskinstance.py", line 465, in _execute_task
    result = _execute_callable(context=context, **execute_callable_kwargs)
             ^^^^^^^^^^^^^^^^^^^^^^^^^^^^^^^^^^^^^^^^^^^^^^^^^^^^^^^^^^^^^
  File "/home/airflow/.local/lib/python3.11/site-packages/airflow/models/taskinstance.py", line 432, in _execute_callable
    return execute_callable(context=context, **execute_callable_kwargs)
           ^^^^^^^^^^^^^^^^^^^^^^^^^^^^^^^^^^^^^^^^^^^^^^^^^^^^^^^^^^^^
  File "/home/airflow/.local/lib/python3.11/site-packages/airflow/models/baseoperator.py", line 400, in wrapper
    return func(self, *args, **kwargs)
           ^^^^^^^^^^^^^^^^^^^^^^^^^^^
  File "/home/airflow/.local/lib/python3.11/site-packages/airflow/decorators/base.py", line 265, in execute
    return_value = super().execute(context)
                   ^^^^^^^^^^^^^^^^^^^^^^^^
  File "/home/airflow/.local/lib/python3.11/site-packages/airflow/models/baseoperator.py", line 400, in wrapper
    return func(self, *args, **kwargs)
           ^^^^^^^^^^^^^^^^^^^^^^^^^^^
  File "/home/airflow/.local/lib/python3.11/site-packages/airflow/operators/python.py", line 235, in execute
    return_value = self.execute_callable()
                   ^^^^^^^^^^^^^^^^^^^^^^^
  File "/home/airflow/.local/lib/python3.11/site-packages/airflow/operators/python.py", line 252, in execute_callable
    return self.python_callable(*self.op_args, **self.op_kwargs)
           ^^^^^^^^^^^^^^^^^^^^^^^^^^^^^^^^^^^^^^^^^^^^^^^^^^^^^
  File "/opt/airflow/dags/etl_dag.py", line 25, in extract
    return _extract().to_dict(orient="records")
           ^^^^^^^^^^
  File "/opt/airflow/app/pipeline.py", line 19, in extract
    return pd.read_csv(CSV_PATH)
           ^^^^^^^^^^^^^^^^^^^^^
  File "/home/airflow/.local/lib/python3.11/site-packages/pandas/io/parsers/readers.py", line 948, in read_csv
    return _read(filepath_or_buffer, kwds)
           ^^^^^^^^^^^^^^^^^^^^^^^^^^^^^^^
  File "/home/airflow/.local/lib/python3.11/site-packages/pandas/io/parsers/readers.py", line 611, in _read
    parser = TextFileReader(filepath_or_buffer, **kwds)
             ^^^^^^^^^^^^^^^^^^^^^^^^^^^^^^^^^^^^^^^^^^
  File "/home/airflow/.local/lib/python3.11/site-packages/pandas/io/parsers/readers.py", line 1448, in __init__
    self._engine = self._make_engine(f, self.engine)
                   ^^^^^^^^^^^^^^^^^^^^^^^^^^^^^^^^^
  File "/home/airflow/.local/lib/python3.11/site-packages/pandas/io/parsers/readers.py", line 1705, in _make_engine
    self.handles = get_handle(
                   ^^^^^^^^^^^
  File "/home/airflow/.local/lib/python3.11/site-packages/pandas/io/common.py", line 863, in get_handle
    handle = open(
             ^^^^^
FileNotFoundError: [Errno 2] No such file or directory: '/app/data/input.csv'
[2025-06-22T15:19:51.641+0000] {taskinstance.py:1206} INFO - Marking task as UP_FOR_RETRY. dag_id=etl_pipeline, task_id=extract, run_id=scheduled__2025-06-21T00:00:00+00:00, execution_date=20250621T000000, start_date=20250622T151951, end_date=20250622T151951
[2025-06-22T15:19:51.654+0000] {standard_task_runner.py:110} ERROR - Failed to execute job 4 for task extract ([Errno 2] No such file or directory: '/app/data/input.csv'; 72)
[2025-06-22T15:19:51.668+0000] {local_task_job_runner.py:240} INFO - Task exited with return code 1
[2025-06-22T15:19:51.685+0000] {taskinstance.py:3498} INFO - 0 downstream tasks scheduled from follow-on schedule check
[2025-06-22T15:19:51.687+0000] {local_task_job_runner.py:222} INFO - ::endgroup::
[2025-06-22T15:29:30.065+0000] {local_task_job_runner.py:120} INFO - ::group::Pre task execution logs
[2025-06-22T15:29:30.159+0000] {taskinstance.py:2076} INFO - Dependencies all met for dep_context=non-requeueable deps ti=<TaskInstance: etl_pipeline.extract scheduled__2025-06-21T00:00:00+00:00 [queued]>
[2025-06-22T15:29:30.165+0000] {taskinstance.py:2076} INFO - Dependencies all met for dep_context=requeueable deps ti=<TaskInstance: etl_pipeline.extract scheduled__2025-06-21T00:00:00+00:00 [queued]>
[2025-06-22T15:29:30.166+0000] {taskinstance.py:2306} INFO - Starting attempt 1 of 2
[2025-06-22T15:29:30.174+0000] {taskinstance.py:2330} INFO - Executing <Task(_PythonDecoratedOperator): extract> on 2025-06-21 00:00:00+00:00
[2025-06-22T15:29:30.179+0000] {standard_task_runner.py:63} INFO - Started process 134 to run task
[2025-06-22T15:29:30.182+0000] {standard_task_runner.py:90} INFO - Running: ['airflow', 'tasks', 'run', 'etl_pipeline', 'extract', 'scheduled__2025-06-21T00:00:00+00:00', '--job-id', '7', '--raw', '--subdir', 'DAGS_FOLDER/etl_dag.py', '--cfg-path', '/tmp/tmphpdf2wav']
[2025-06-22T15:29:30.183+0000] {standard_task_runner.py:91} INFO - Job 7: Subtask extract
[2025-06-22T15:29:30.223+0000] {task_command.py:426} INFO - Running <TaskInstance: etl_pipeline.extract scheduled__2025-06-21T00:00:00+00:00 [running]> on host ecff408c7856
[2025-06-22T15:29:30.286+0000] {taskinstance.py:2648} INFO - Exporting env vars: AIRFLOW_CTX_DAG_OWNER='airflow' AIRFLOW_CTX_DAG_ID='etl_pipeline' AIRFLOW_CTX_TASK_ID='extract' AIRFLOW_CTX_EXECUTION_DATE='2025-06-21T00:00:00+00:00' AIRFLOW_CTX_TRY_NUMBER='1' AIRFLOW_CTX_DAG_RUN_ID='scheduled__2025-06-21T00:00:00+00:00'
[2025-06-22T15:29:30.287+0000] {taskinstance.py:430} INFO - ::endgroup::
[2025-06-22T15:29:30.288+0000] {taskinstance.py:441} INFO - ::group::Post task execution logs
[2025-06-22T15:29:30.289+0000] {taskinstance.py:2905} ERROR - Task failed with exception
Traceback (most recent call last):
  File "/home/airflow/.local/lib/python3.11/site-packages/airflow/models/taskinstance.py", line 465, in _execute_task
    result = _execute_callable(context=context, **execute_callable_kwargs)
             ^^^^^^^^^^^^^^^^^^^^^^^^^^^^^^^^^^^^^^^^^^^^^^^^^^^^^^^^^^^^^
  File "/home/airflow/.local/lib/python3.11/site-packages/airflow/models/taskinstance.py", line 432, in _execute_callable
    return execute_callable(context=context, **execute_callable_kwargs)
           ^^^^^^^^^^^^^^^^^^^^^^^^^^^^^^^^^^^^^^^^^^^^^^^^^^^^^^^^^^^^
  File "/home/airflow/.local/lib/python3.11/site-packages/airflow/models/baseoperator.py", line 400, in wrapper
    return func(self, *args, **kwargs)
           ^^^^^^^^^^^^^^^^^^^^^^^^^^^
  File "/home/airflow/.local/lib/python3.11/site-packages/airflow/decorators/base.py", line 265, in execute
    return_value = super().execute(context)
                   ^^^^^^^^^^^^^^^^^^^^^^^^
  File "/home/airflow/.local/lib/python3.11/site-packages/airflow/models/baseoperator.py", line 400, in wrapper
    return func(self, *args, **kwargs)
           ^^^^^^^^^^^^^^^^^^^^^^^^^^^
  File "/home/airflow/.local/lib/python3.11/site-packages/airflow/operators/python.py", line 235, in execute
    return_value = self.execute_callable()
                   ^^^^^^^^^^^^^^^^^^^^^^^
  File "/home/airflow/.local/lib/python3.11/site-packages/airflow/operators/python.py", line 252, in execute_callable
    return self.python_callable(*self.op_args, **self.op_kwargs)
           ^^^^^^^^^^^^^^^^^^^^^^^^^^^^^^^^^^^^^^^^^^^^^^^^^^^^^
  File "/opt/airflow/dags/etl_dag.py", line 25, in extract
    return _extract().to_dict(orient="records")
           ^^^^^^^^^^
  File "/opt/airflow/app/pipeline.py", line 19, in extract
    return pd.read_csv(CSV_PATH)
           ^^^^^^^^^^^^^^^^^^^^^
  File "/home/airflow/.local/lib/python3.11/site-packages/pandas/io/parsers/readers.py", line 948, in read_csv
    return _read(filepath_or_buffer, kwds)
           ^^^^^^^^^^^^^^^^^^^^^^^^^^^^^^^
  File "/home/airflow/.local/lib/python3.11/site-packages/pandas/io/parsers/readers.py", line 611, in _read
    parser = TextFileReader(filepath_or_buffer, **kwds)
             ^^^^^^^^^^^^^^^^^^^^^^^^^^^^^^^^^^^^^^^^^^
  File "/home/airflow/.local/lib/python3.11/site-packages/pandas/io/parsers/readers.py", line 1448, in __init__
    self._engine = self._make_engine(f, self.engine)
                   ^^^^^^^^^^^^^^^^^^^^^^^^^^^^^^^^^
  File "/home/airflow/.local/lib/python3.11/site-packages/pandas/io/parsers/readers.py", line 1705, in _make_engine
    self.handles = get_handle(
                   ^^^^^^^^^^^
  File "/home/airflow/.local/lib/python3.11/site-packages/pandas/io/common.py", line 863, in get_handle
    handle = open(
             ^^^^^
FileNotFoundError: [Errno 2] No such file or directory: '/app/data/input.csv'
[2025-06-22T15:29:30.298+0000] {taskinstance.py:1206} INFO - Marking task as UP_FOR_RETRY. dag_id=etl_pipeline, task_id=extract, run_id=scheduled__2025-06-21T00:00:00+00:00, execution_date=20250621T000000, start_date=20250622T152930, end_date=20250622T152930
[2025-06-22T15:29:30.306+0000] {standard_task_runner.py:110} ERROR - Failed to execute job 7 for task extract ([Errno 2] No such file or directory: '/app/data/input.csv'; 134)
[2025-06-22T15:29:30.339+0000] {local_task_job_runner.py:240} INFO - Task exited with return code 1
[2025-06-22T15:29:30.356+0000] {taskinstance.py:3498} INFO - 0 downstream tasks scheduled from follow-on schedule check
[2025-06-22T15:29:30.358+0000] {local_task_job_runner.py:222} INFO - ::endgroup::
[2025-06-22T15:35:35.572+0000] {local_task_job_runner.py:120} INFO - ::group::Pre task execution logs
[2025-06-22T15:35:35.662+0000] {taskinstance.py:2076} INFO - Dependencies all met for dep_context=non-requeueable deps ti=<TaskInstance: etl_pipeline.extract scheduled__2025-06-21T00:00:00+00:00 [queued]>
[2025-06-22T15:35:35.668+0000] {taskinstance.py:2076} INFO - Dependencies all met for dep_context=requeueable deps ti=<TaskInstance: etl_pipeline.extract scheduled__2025-06-21T00:00:00+00:00 [queued]>
[2025-06-22T15:35:35.669+0000] {taskinstance.py:2306} INFO - Starting attempt 1 of 2
[2025-06-22T15:35:35.678+0000] {taskinstance.py:2330} INFO - Executing <Task(_PythonDecoratedOperator): extract> on 2025-06-21 00:00:00+00:00
[2025-06-22T15:35:35.683+0000] {standard_task_runner.py:63} INFO - Started process 190 to run task
[2025-06-22T15:35:35.685+0000] {standard_task_runner.py:90} INFO - Running: ['airflow', 'tasks', 'run', 'etl_pipeline', 'extract', 'scheduled__2025-06-21T00:00:00+00:00', '--job-id', '11', '--raw', '--subdir', 'DAGS_FOLDER/etl_dag.py', '--cfg-path', '/tmp/tmpzvso9z30']
[2025-06-22T15:35:35.687+0000] {standard_task_runner.py:91} INFO - Job 11: Subtask extract
[2025-06-22T15:35:35.729+0000] {task_command.py:426} INFO - Running <TaskInstance: etl_pipeline.extract scheduled__2025-06-21T00:00:00+00:00 [running]> on host ecff408c7856
[2025-06-22T15:35:35.795+0000] {taskinstance.py:2648} INFO - Exporting env vars: AIRFLOW_CTX_DAG_OWNER='airflow' AIRFLOW_CTX_DAG_ID='etl_pipeline' AIRFLOW_CTX_TASK_ID='extract' AIRFLOW_CTX_EXECUTION_DATE='2025-06-21T00:00:00+00:00' AIRFLOW_CTX_TRY_NUMBER='1' AIRFLOW_CTX_DAG_RUN_ID='scheduled__2025-06-21T00:00:00+00:00'
[2025-06-22T15:35:35.796+0000] {taskinstance.py:430} INFO - ::endgroup::
[2025-06-22T15:35:35.798+0000] {taskinstance.py:441} INFO - ::group::Post task execution logs
[2025-06-22T15:35:35.798+0000] {taskinstance.py:2905} ERROR - Task failed with exception
Traceback (most recent call last):
  File "/home/airflow/.local/lib/python3.11/site-packages/airflow/models/taskinstance.py", line 465, in _execute_task
    result = _execute_callable(context=context, **execute_callable_kwargs)
             ^^^^^^^^^^^^^^^^^^^^^^^^^^^^^^^^^^^^^^^^^^^^^^^^^^^^^^^^^^^^^
  File "/home/airflow/.local/lib/python3.11/site-packages/airflow/models/taskinstance.py", line 432, in _execute_callable
    return execute_callable(context=context, **execute_callable_kwargs)
           ^^^^^^^^^^^^^^^^^^^^^^^^^^^^^^^^^^^^^^^^^^^^^^^^^^^^^^^^^^^^
  File "/home/airflow/.local/lib/python3.11/site-packages/airflow/models/baseoperator.py", line 400, in wrapper
    return func(self, *args, **kwargs)
           ^^^^^^^^^^^^^^^^^^^^^^^^^^^
  File "/home/airflow/.local/lib/python3.11/site-packages/airflow/decorators/base.py", line 265, in execute
    return_value = super().execute(context)
                   ^^^^^^^^^^^^^^^^^^^^^^^^
  File "/home/airflow/.local/lib/python3.11/site-packages/airflow/models/baseoperator.py", line 400, in wrapper
    return func(self, *args, **kwargs)
           ^^^^^^^^^^^^^^^^^^^^^^^^^^^
  File "/home/airflow/.local/lib/python3.11/site-packages/airflow/operators/python.py", line 235, in execute
    return_value = self.execute_callable()
                   ^^^^^^^^^^^^^^^^^^^^^^^
  File "/home/airflow/.local/lib/python3.11/site-packages/airflow/operators/python.py", line 252, in execute_callable
    return self.python_callable(*self.op_args, **self.op_kwargs)
           ^^^^^^^^^^^^^^^^^^^^^^^^^^^^^^^^^^^^^^^^^^^^^^^^^^^^^
  File "/opt/airflow/dags/etl_dag.py", line 25, in extract
    return _extract().to_dict(orient="records")
           ^^^^^^^^^^
  File "/opt/airflow/app/pipeline.py", line 19, in extract
    return pd.read_csv(CSV_PATH)
           ^^^^^^^^^^^^^^^^^^^^^
  File "/home/airflow/.local/lib/python3.11/site-packages/pandas/io/parsers/readers.py", line 948, in read_csv
    return _read(filepath_or_buffer, kwds)
           ^^^^^^^^^^^^^^^^^^^^^^^^^^^^^^^
  File "/home/airflow/.local/lib/python3.11/site-packages/pandas/io/parsers/readers.py", line 611, in _read
    parser = TextFileReader(filepath_or_buffer, **kwds)
             ^^^^^^^^^^^^^^^^^^^^^^^^^^^^^^^^^^^^^^^^^^
  File "/home/airflow/.local/lib/python3.11/site-packages/pandas/io/parsers/readers.py", line 1448, in __init__
    self._engine = self._make_engine(f, self.engine)
                   ^^^^^^^^^^^^^^^^^^^^^^^^^^^^^^^^^
  File "/home/airflow/.local/lib/python3.11/site-packages/pandas/io/parsers/readers.py", line 1705, in _make_engine
    self.handles = get_handle(
                   ^^^^^^^^^^^
  File "/home/airflow/.local/lib/python3.11/site-packages/pandas/io/common.py", line 863, in get_handle
    handle = open(
             ^^^^^
FileNotFoundError: [Errno 2] No such file or directory: '/app/data/input.csv'
[2025-06-22T15:35:35.807+0000] {taskinstance.py:1206} INFO - Marking task as UP_FOR_RETRY. dag_id=etl_pipeline, task_id=extract, run_id=scheduled__2025-06-21T00:00:00+00:00, execution_date=20250621T000000, start_date=20250622T153535, end_date=20250622T153535
[2025-06-22T15:35:35.815+0000] {standard_task_runner.py:110} ERROR - Failed to execute job 11 for task extract ([Errno 2] No such file or directory: '/app/data/input.csv'; 190)
[2025-06-22T15:35:35.823+0000] {local_task_job_runner.py:240} INFO - Task exited with return code 1
[2025-06-22T15:35:35.839+0000] {taskinstance.py:3498} INFO - 0 downstream tasks scheduled from follow-on schedule check
[2025-06-22T15:35:35.841+0000] {local_task_job_runner.py:222} INFO - ::endgroup::
[2025-06-22T15:45:44.231+0000] {local_task_job_runner.py:120} INFO - ::group::Pre task execution logs
[2025-06-22T15:45:44.350+0000] {taskinstance.py:2076} INFO - Dependencies all met for dep_context=non-requeueable deps ti=<TaskInstance: etl_pipeline.extract scheduled__2025-06-21T00:00:00+00:00 [queued]>
[2025-06-22T15:45:44.359+0000] {taskinstance.py:2076} INFO - Dependencies all met for dep_context=requeueable deps ti=<TaskInstance: etl_pipeline.extract scheduled__2025-06-21T00:00:00+00:00 [queued]>
[2025-06-22T15:45:44.360+0000] {taskinstance.py:2306} INFO - Starting attempt 1 of 2
[2025-06-22T15:45:44.372+0000] {taskinstance.py:2330} INFO - Executing <Task(_PythonDecoratedOperator): extract> on 2025-06-21 00:00:00+00:00
[2025-06-22T15:45:44.378+0000] {standard_task_runner.py:63} INFO - Started process 270 to run task
[2025-06-22T15:45:44.383+0000] {standard_task_runner.py:90} INFO - Running: ['airflow', 'tasks', 'run', 'etl_pipeline', 'extract', 'scheduled__2025-06-21T00:00:00+00:00', '--job-id', '16', '--raw', '--subdir', 'DAGS_FOLDER/etl_dag.py', '--cfg-path', '/tmp/tmpt8mh0i18']
[2025-06-22T15:45:44.386+0000] {standard_task_runner.py:91} INFO - Job 16: Subtask extract
[2025-06-22T15:45:44.440+0000] {task_command.py:426} INFO - Running <TaskInstance: etl_pipeline.extract scheduled__2025-06-21T00:00:00+00:00 [running]> on host ecff408c7856
[2025-06-22T15:45:44.526+0000] {taskinstance.py:2648} INFO - Exporting env vars: AIRFLOW_CTX_DAG_OWNER='airflow' AIRFLOW_CTX_DAG_ID='etl_pipeline' AIRFLOW_CTX_TASK_ID='extract' AIRFLOW_CTX_EXECUTION_DATE='2025-06-21T00:00:00+00:00' AIRFLOW_CTX_TRY_NUMBER='1' AIRFLOW_CTX_DAG_RUN_ID='scheduled__2025-06-21T00:00:00+00:00'
[2025-06-22T15:45:44.527+0000] {taskinstance.py:430} INFO - ::endgroup::
[2025-06-22T15:45:44.529+0000] {taskinstance.py:441} INFO - ::group::Post task execution logs
[2025-06-22T15:45:44.529+0000] {taskinstance.py:2905} ERROR - Task failed with exception
Traceback (most recent call last):
  File "/home/airflow/.local/lib/python3.11/site-packages/airflow/models/taskinstance.py", line 465, in _execute_task
    result = _execute_callable(context=context, **execute_callable_kwargs)
             ^^^^^^^^^^^^^^^^^^^^^^^^^^^^^^^^^^^^^^^^^^^^^^^^^^^^^^^^^^^^^
  File "/home/airflow/.local/lib/python3.11/site-packages/airflow/models/taskinstance.py", line 432, in _execute_callable
    return execute_callable(context=context, **execute_callable_kwargs)
           ^^^^^^^^^^^^^^^^^^^^^^^^^^^^^^^^^^^^^^^^^^^^^^^^^^^^^^^^^^^^
  File "/home/airflow/.local/lib/python3.11/site-packages/airflow/models/baseoperator.py", line 400, in wrapper
    return func(self, *args, **kwargs)
           ^^^^^^^^^^^^^^^^^^^^^^^^^^^
  File "/home/airflow/.local/lib/python3.11/site-packages/airflow/decorators/base.py", line 265, in execute
    return_value = super().execute(context)
                   ^^^^^^^^^^^^^^^^^^^^^^^^
  File "/home/airflow/.local/lib/python3.11/site-packages/airflow/models/baseoperator.py", line 400, in wrapper
    return func(self, *args, **kwargs)
           ^^^^^^^^^^^^^^^^^^^^^^^^^^^
  File "/home/airflow/.local/lib/python3.11/site-packages/airflow/operators/python.py", line 235, in execute
    return_value = self.execute_callable()
                   ^^^^^^^^^^^^^^^^^^^^^^^
  File "/home/airflow/.local/lib/python3.11/site-packages/airflow/operators/python.py", line 252, in execute_callable
    return self.python_callable(*self.op_args, **self.op_kwargs)
           ^^^^^^^^^^^^^^^^^^^^^^^^^^^^^^^^^^^^^^^^^^^^^^^^^^^^^
  File "/opt/airflow/dags/etl_dag.py", line 25, in extract
    return _extract().to_dict(orient="records")
           ^^^^^^^^^^
  File "/opt/airflow/app/pipeline.py", line 19, in extract
    return pd.read_csv(CSV_PATH)
           ^^^^^^^^^^^^^^^^^^^^^
  File "/home/airflow/.local/lib/python3.11/site-packages/pandas/io/parsers/readers.py", line 948, in read_csv
    return _read(filepath_or_buffer, kwds)
           ^^^^^^^^^^^^^^^^^^^^^^^^^^^^^^^
  File "/home/airflow/.local/lib/python3.11/site-packages/pandas/io/parsers/readers.py", line 611, in _read
    parser = TextFileReader(filepath_or_buffer, **kwds)
             ^^^^^^^^^^^^^^^^^^^^^^^^^^^^^^^^^^^^^^^^^^
  File "/home/airflow/.local/lib/python3.11/site-packages/pandas/io/parsers/readers.py", line 1448, in __init__
    self._engine = self._make_engine(f, self.engine)
                   ^^^^^^^^^^^^^^^^^^^^^^^^^^^^^^^^^
  File "/home/airflow/.local/lib/python3.11/site-packages/pandas/io/parsers/readers.py", line 1705, in _make_engine
    self.handles = get_handle(
                   ^^^^^^^^^^^
  File "/home/airflow/.local/lib/python3.11/site-packages/pandas/io/common.py", line 863, in get_handle
    handle = open(
             ^^^^^
FileNotFoundError: [Errno 2] No such file or directory: '/app/data/input.csv'
[2025-06-22T15:45:44.539+0000] {taskinstance.py:1206} INFO - Marking task as UP_FOR_RETRY. dag_id=etl_pipeline, task_id=extract, run_id=scheduled__2025-06-21T00:00:00+00:00, execution_date=20250621T000000, start_date=20250622T154544, end_date=20250622T154544
[2025-06-22T15:45:44.548+0000] {standard_task_runner.py:110} ERROR - Failed to execute job 16 for task extract ([Errno 2] No such file or directory: '/app/data/input.csv'; 270)
[2025-06-22T15:45:44.558+0000] {local_task_job_runner.py:240} INFO - Task exited with return code 1
[2025-06-22T15:45:44.575+0000] {taskinstance.py:3498} INFO - 0 downstream tasks scheduled from follow-on schedule check
[2025-06-22T15:45:44.577+0000] {local_task_job_runner.py:222} INFO - ::endgroup::
