[2025-06-22T15:25:38.392+0000] {local_task_job_runner.py:120} INFO - ::group::Pre task execution logs
[2025-06-22T15:25:38.485+0000] {taskinstance.py:2076} INFO - Dependencies all met for dep_context=non-requeueable deps ti=<TaskInstance: etl_pipeline.extract scheduled__2025-06-21T00:00:00+00:00 [queued]>
[2025-06-22T15:25:38.491+0000] {taskinstance.py:2076} INFO - Dependencies all met for dep_context=requeueable deps ti=<TaskInstance: etl_pipeline.extract scheduled__2025-06-21T00:00:00+00:00 [queued]>
[2025-06-22T15:25:38.491+0000] {taskinstance.py:2306} INFO - Starting attempt 2 of 2
[2025-06-22T15:25:38.500+0000] {taskinstance.py:2330} INFO - Executing <Task(_PythonDecoratedOperator): extract> on 2025-06-21 00:00:00+00:00
[2025-06-22T15:25:38.507+0000] {standard_task_runner.py:63} INFO - Started process 102 to run task
[2025-06-22T15:25:38.509+0000] {standard_task_runner.py:90} INFO - Running: ['airflow', 'tasks', 'run', 'etl_pipeline', 'extract', 'scheduled__2025-06-21T00:00:00+00:00', '--job-id', '5', '--raw', '--subdir', 'DAGS_FOLDER/etl_dag.py', '--cfg-path', '/tmp/tmp64sb7nvu']
[2025-06-22T15:25:38.511+0000] {standard_task_runner.py:91} INFO - Job 5: Subtask extract
[2025-06-22T15:25:38.558+0000] {task_command.py:426} INFO - Running <TaskInstance: etl_pipeline.extract scheduled__2025-06-21T00:00:00+00:00 [running]> on host ecff408c7856
[2025-06-22T15:25:38.619+0000] {taskinstance.py:2648} INFO - Exporting env vars: AIRFLOW_CTX_DAG_OWNER='airflow' AIRFLOW_CTX_DAG_ID='etl_pipeline' AIRFLOW_CTX_TASK_ID='extract' AIRFLOW_CTX_EXECUTION_DATE='2025-06-21T00:00:00+00:00' AIRFLOW_CTX_TRY_NUMBER='2' AIRFLOW_CTX_DAG_RUN_ID='scheduled__2025-06-21T00:00:00+00:00'
[2025-06-22T15:25:38.620+0000] {taskinstance.py:430} INFO - ::endgroup::
[2025-06-22T15:25:38.621+0000] {taskinstance.py:441} INFO - ::group::Post task execution logs
[2025-06-22T15:25:38.622+0000] {taskinstance.py:2905} ERROR - Task failed with exception
Traceback (most recent call last):
  File "/home/airflow/.local/lib/python3.11/site-packages/airflow/models/taskinstance.py", line 465, in _execute_task
    result = _execute_callable(context=context, **execute_callable_kwargs)
             ^^^^^^^^^^^^^^^^^^^^^^^^^^^^^^^^^^^^^^^^^^^^^^^^^^^^^^^^^^^^^
  File "/home/airflow/.local/lib/python3.11/site-packages/airflow/models/taskinstance.py", line 432, in _execute_callable
    return execute_callable(context=context, **execute_callable_kwargs)
           ^^^^^^^^^^^^^^^^^^^^^^^^^^^^^^^^^^^^^^^^^^^^^^^^^^^^^^^^^^^^
  File "/home/airflow/.local/lib/python3.11/site-packages/airflow/models/baseoperator.py", line 400, in wrapper
    return func(self, *args, **kwargs)
           ^^^^^^^^^^^^^^^^^^^^^^^^^^^
  File "/home/airflow/.local/lib/python3.11/site-packages/airflow/decorators/base.py", line 265, in execute
    return_value = super().execute(context)
                   ^^^^^^^^^^^^^^^^^^^^^^^^
  File "/home/airflow/.local/lib/python3.11/site-packages/airflow/models/baseoperator.py", line 400, in wrapper
    return func(self, *args, **kwargs)
           ^^^^^^^^^^^^^^^^^^^^^^^^^^^
  File "/home/airflow/.local/lib/python3.11/site-packages/airflow/operators/python.py", line 235, in execute
    return_value = self.execute_callable()
                   ^^^^^^^^^^^^^^^^^^^^^^^
  File "/home/airflow/.local/lib/python3.11/site-packages/airflow/operators/python.py", line 252, in execute_callable
    return self.python_callable(*self.op_args, **self.op_kwargs)
           ^^^^^^^^^^^^^^^^^^^^^^^^^^^^^^^^^^^^^^^^^^^^^^^^^^^^^
  File "/opt/airflow/dags/etl_dag.py", line 25, in extract
    return _extract().to_dict(orient="records")
           ^^^^^^^^^^
  File "/opt/airflow/app/pipeline.py", line 19, in extract
    return pd.read_csv(CSV_PATH)
           ^^^^^^^^^^^^^^^^^^^^^
  File "/home/airflow/.local/lib/python3.11/site-packages/pandas/io/parsers/readers.py", line 948, in read_csv
    return _read(filepath_or_buffer, kwds)
           ^^^^^^^^^^^^^^^^^^^^^^^^^^^^^^^
  File "/home/airflow/.local/lib/python3.11/site-packages/pandas/io/parsers/readers.py", line 611, in _read
    parser = TextFileReader(filepath_or_buffer, **kwds)
             ^^^^^^^^^^^^^^^^^^^^^^^^^^^^^^^^^^^^^^^^^^
  File "/home/airflow/.local/lib/python3.11/site-packages/pandas/io/parsers/readers.py", line 1448, in __init__
    self._engine = self._make_engine(f, self.engine)
                   ^^^^^^^^^^^^^^^^^^^^^^^^^^^^^^^^^
  File "/home/airflow/.local/lib/python3.11/site-packages/pandas/io/parsers/readers.py", line 1705, in _make_engine
    self.handles = get_handle(
                   ^^^^^^^^^^^
  File "/home/airflow/.local/lib/python3.11/site-packages/pandas/io/common.py", line 863, in get_handle
    handle = open(
             ^^^^^
FileNotFoundError: [Errno 2] No such file or directory: '/app/data/input.csv'
[2025-06-22T15:25:38.631+0000] {taskinstance.py:1206} INFO - Marking task as FAILED. dag_id=etl_pipeline, task_id=extract, run_id=scheduled__2025-06-21T00:00:00+00:00, execution_date=20250621T000000, start_date=20250622T152538, end_date=20250622T152538
[2025-06-22T15:25:38.639+0000] {standard_task_runner.py:110} ERROR - Failed to execute job 5 for task extract ([Errno 2] No such file or directory: '/app/data/input.csv'; 102)
[2025-06-22T15:25:38.661+0000] {local_task_job_runner.py:240} INFO - Task exited with return code 1
[2025-06-22T15:25:38.679+0000] {taskinstance.py:3498} INFO - 0 downstream tasks scheduled from follow-on schedule check
[2025-06-22T15:25:38.682+0000] {local_task_job_runner.py:222} INFO - ::endgroup::
[2025-06-22T15:34:33.026+0000] {local_task_job_runner.py:120} INFO - ::group::Pre task execution logs
[2025-06-22T15:34:33.129+0000] {taskinstance.py:2076} INFO - Dependencies all met for dep_context=non-requeueable deps ti=<TaskInstance: etl_pipeline.extract scheduled__2025-06-21T00:00:00+00:00 [queued]>
[2025-06-22T15:34:33.136+0000] {taskinstance.py:2076} INFO - Dependencies all met for dep_context=requeueable deps ti=<TaskInstance: etl_pipeline.extract scheduled__2025-06-21T00:00:00+00:00 [queued]>
[2025-06-22T15:34:33.136+0000] {taskinstance.py:2306} INFO - Starting attempt 2 of 2
[2025-06-22T15:34:33.148+0000] {taskinstance.py:2330} INFO - Executing <Task(_PythonDecoratedOperator): extract> on 2025-06-21 00:00:00+00:00
[2025-06-22T15:34:33.155+0000] {standard_task_runner.py:63} INFO - Started process 170 to run task
[2025-06-22T15:34:33.158+0000] {standard_task_runner.py:90} INFO - Running: ['airflow', 'tasks', 'run', 'etl_pipeline', 'extract', 'scheduled__2025-06-21T00:00:00+00:00', '--job-id', '9', '--raw', '--subdir', 'DAGS_FOLDER/etl_dag.py', '--cfg-path', '/tmp/tmp6q3ejeus']
[2025-06-22T15:34:33.160+0000] {standard_task_runner.py:91} INFO - Job 9: Subtask extract
[2025-06-22T15:34:33.208+0000] {task_command.py:426} INFO - Running <TaskInstance: etl_pipeline.extract scheduled__2025-06-21T00:00:00+00:00 [running]> on host ecff408c7856
[2025-06-22T15:34:33.276+0000] {taskinstance.py:2648} INFO - Exporting env vars: AIRFLOW_CTX_DAG_OWNER='airflow' AIRFLOW_CTX_DAG_ID='etl_pipeline' AIRFLOW_CTX_TASK_ID='extract' AIRFLOW_CTX_EXECUTION_DATE='2025-06-21T00:00:00+00:00' AIRFLOW_CTX_TRY_NUMBER='2' AIRFLOW_CTX_DAG_RUN_ID='scheduled__2025-06-21T00:00:00+00:00'
[2025-06-22T15:34:33.277+0000] {taskinstance.py:430} INFO - ::endgroup::
[2025-06-22T15:34:33.279+0000] {taskinstance.py:441} INFO - ::group::Post task execution logs
[2025-06-22T15:34:33.279+0000] {taskinstance.py:2905} ERROR - Task failed with exception
Traceback (most recent call last):
  File "/home/airflow/.local/lib/python3.11/site-packages/airflow/models/taskinstance.py", line 465, in _execute_task
    result = _execute_callable(context=context, **execute_callable_kwargs)
             ^^^^^^^^^^^^^^^^^^^^^^^^^^^^^^^^^^^^^^^^^^^^^^^^^^^^^^^^^^^^^
  File "/home/airflow/.local/lib/python3.11/site-packages/airflow/models/taskinstance.py", line 432, in _execute_callable
    return execute_callable(context=context, **execute_callable_kwargs)
           ^^^^^^^^^^^^^^^^^^^^^^^^^^^^^^^^^^^^^^^^^^^^^^^^^^^^^^^^^^^^
  File "/home/airflow/.local/lib/python3.11/site-packages/airflow/models/baseoperator.py", line 400, in wrapper
    return func(self, *args, **kwargs)
           ^^^^^^^^^^^^^^^^^^^^^^^^^^^
  File "/home/airflow/.local/lib/python3.11/site-packages/airflow/decorators/base.py", line 265, in execute
    return_value = super().execute(context)
                   ^^^^^^^^^^^^^^^^^^^^^^^^
  File "/home/airflow/.local/lib/python3.11/site-packages/airflow/models/baseoperator.py", line 400, in wrapper
    return func(self, *args, **kwargs)
           ^^^^^^^^^^^^^^^^^^^^^^^^^^^
  File "/home/airflow/.local/lib/python3.11/site-packages/airflow/operators/python.py", line 235, in execute
    return_value = self.execute_callable()
                   ^^^^^^^^^^^^^^^^^^^^^^^
  File "/home/airflow/.local/lib/python3.11/site-packages/airflow/operators/python.py", line 252, in execute_callable
    return self.python_callable(*self.op_args, **self.op_kwargs)
           ^^^^^^^^^^^^^^^^^^^^^^^^^^^^^^^^^^^^^^^^^^^^^^^^^^^^^
  File "/opt/airflow/dags/etl_dag.py", line 25, in extract
    return _extract().to_dict(orient="records")
           ^^^^^^^^^^
  File "/opt/airflow/app/pipeline.py", line 19, in extract
    return pd.read_csv(CSV_PATH)
           ^^^^^^^^^^^^^^^^^^^^^
  File "/home/airflow/.local/lib/python3.11/site-packages/pandas/io/parsers/readers.py", line 948, in read_csv
    return _read(filepath_or_buffer, kwds)
           ^^^^^^^^^^^^^^^^^^^^^^^^^^^^^^^
  File "/home/airflow/.local/lib/python3.11/site-packages/pandas/io/parsers/readers.py", line 611, in _read
    parser = TextFileReader(filepath_or_buffer, **kwds)
             ^^^^^^^^^^^^^^^^^^^^^^^^^^^^^^^^^^^^^^^^^^
  File "/home/airflow/.local/lib/python3.11/site-packages/pandas/io/parsers/readers.py", line 1448, in __init__
    self._engine = self._make_engine(f, self.engine)
                   ^^^^^^^^^^^^^^^^^^^^^^^^^^^^^^^^^
  File "/home/airflow/.local/lib/python3.11/site-packages/pandas/io/parsers/readers.py", line 1705, in _make_engine
    self.handles = get_handle(
                   ^^^^^^^^^^^
  File "/home/airflow/.local/lib/python3.11/site-packages/pandas/io/common.py", line 863, in get_handle
    handle = open(
             ^^^^^
FileNotFoundError: [Errno 2] No such file or directory: '/app/data/input.csv'
[2025-06-22T15:34:33.292+0000] {taskinstance.py:1206} INFO - Marking task as FAILED. dag_id=etl_pipeline, task_id=extract, run_id=scheduled__2025-06-21T00:00:00+00:00, execution_date=20250621T000000, start_date=20250622T153433, end_date=20250622T153433
[2025-06-22T15:34:33.300+0000] {standard_task_runner.py:110} ERROR - Failed to execute job 9 for task extract ([Errno 2] No such file or directory: '/app/data/input.csv'; 170)
[2025-06-22T15:34:33.334+0000] {local_task_job_runner.py:240} INFO - Task exited with return code 1
[2025-06-22T15:34:33.357+0000] {taskinstance.py:3498} INFO - 0 downstream tasks scheduled from follow-on schedule check
[2025-06-22T15:34:33.364+0000] {local_task_job_runner.py:222} INFO - ::endgroup::
[2025-06-22T15:40:38.226+0000] {local_task_job_runner.py:120} INFO - ::group::Pre task execution logs
[2025-06-22T15:40:38.334+0000] {taskinstance.py:2076} INFO - Dependencies all met for dep_context=non-requeueable deps ti=<TaskInstance: etl_pipeline.extract scheduled__2025-06-21T00:00:00+00:00 [queued]>
[2025-06-22T15:40:38.342+0000] {taskinstance.py:2076} INFO - Dependencies all met for dep_context=requeueable deps ti=<TaskInstance: etl_pipeline.extract scheduled__2025-06-21T00:00:00+00:00 [queued]>
[2025-06-22T15:40:38.342+0000] {taskinstance.py:2306} INFO - Starting attempt 2 of 2
[2025-06-22T15:40:38.352+0000] {taskinstance.py:2330} INFO - Executing <Task(_PythonDecoratedOperator): extract> on 2025-06-21 00:00:00+00:00
[2025-06-22T15:40:38.358+0000] {standard_task_runner.py:63} INFO - Started process 226 to run task
[2025-06-22T15:40:38.361+0000] {standard_task_runner.py:90} INFO - Running: ['airflow', 'tasks', 'run', 'etl_pipeline', 'extract', 'scheduled__2025-06-21T00:00:00+00:00', '--job-id', '13', '--raw', '--subdir', 'DAGS_FOLDER/etl_dag.py', '--cfg-path', '/tmp/tmp4toh4seq']
[2025-06-22T15:40:38.363+0000] {standard_task_runner.py:91} INFO - Job 13: Subtask extract
[2025-06-22T15:40:38.411+0000] {task_command.py:426} INFO - Running <TaskInstance: etl_pipeline.extract scheduled__2025-06-21T00:00:00+00:00 [running]> on host ecff408c7856
[2025-06-22T15:40:38.479+0000] {taskinstance.py:2648} INFO - Exporting env vars: AIRFLOW_CTX_DAG_OWNER='airflow' AIRFLOW_CTX_DAG_ID='etl_pipeline' AIRFLOW_CTX_TASK_ID='extract' AIRFLOW_CTX_EXECUTION_DATE='2025-06-21T00:00:00+00:00' AIRFLOW_CTX_TRY_NUMBER='2' AIRFLOW_CTX_DAG_RUN_ID='scheduled__2025-06-21T00:00:00+00:00'
[2025-06-22T15:40:38.480+0000] {taskinstance.py:430} INFO - ::endgroup::
[2025-06-22T15:40:38.481+0000] {taskinstance.py:441} INFO - ::group::Post task execution logs
[2025-06-22T15:40:38.482+0000] {taskinstance.py:2905} ERROR - Task failed with exception
Traceback (most recent call last):
  File "/home/airflow/.local/lib/python3.11/site-packages/airflow/models/taskinstance.py", line 465, in _execute_task
    result = _execute_callable(context=context, **execute_callable_kwargs)
             ^^^^^^^^^^^^^^^^^^^^^^^^^^^^^^^^^^^^^^^^^^^^^^^^^^^^^^^^^^^^^
  File "/home/airflow/.local/lib/python3.11/site-packages/airflow/models/taskinstance.py", line 432, in _execute_callable
    return execute_callable(context=context, **execute_callable_kwargs)
           ^^^^^^^^^^^^^^^^^^^^^^^^^^^^^^^^^^^^^^^^^^^^^^^^^^^^^^^^^^^^
  File "/home/airflow/.local/lib/python3.11/site-packages/airflow/models/baseoperator.py", line 400, in wrapper
    return func(self, *args, **kwargs)
           ^^^^^^^^^^^^^^^^^^^^^^^^^^^
  File "/home/airflow/.local/lib/python3.11/site-packages/airflow/decorators/base.py", line 265, in execute
    return_value = super().execute(context)
                   ^^^^^^^^^^^^^^^^^^^^^^^^
  File "/home/airflow/.local/lib/python3.11/site-packages/airflow/models/baseoperator.py", line 400, in wrapper
    return func(self, *args, **kwargs)
           ^^^^^^^^^^^^^^^^^^^^^^^^^^^
  File "/home/airflow/.local/lib/python3.11/site-packages/airflow/operators/python.py", line 235, in execute
    return_value = self.execute_callable()
                   ^^^^^^^^^^^^^^^^^^^^^^^
  File "/home/airflow/.local/lib/python3.11/site-packages/airflow/operators/python.py", line 252, in execute_callable
    return self.python_callable(*self.op_args, **self.op_kwargs)
           ^^^^^^^^^^^^^^^^^^^^^^^^^^^^^^^^^^^^^^^^^^^^^^^^^^^^^
  File "/opt/airflow/dags/etl_dag.py", line 25, in extract
    return _extract().to_dict(orient="records")
           ^^^^^^^^^^
  File "/opt/airflow/app/pipeline.py", line 19, in extract
    return pd.read_csv(CSV_PATH)
           ^^^^^^^^^^^^^^^^^^^^^
  File "/home/airflow/.local/lib/python3.11/site-packages/pandas/io/parsers/readers.py", line 948, in read_csv
    return _read(filepath_or_buffer, kwds)
           ^^^^^^^^^^^^^^^^^^^^^^^^^^^^^^^
  File "/home/airflow/.local/lib/python3.11/site-packages/pandas/io/parsers/readers.py", line 611, in _read
    parser = TextFileReader(filepath_or_buffer, **kwds)
             ^^^^^^^^^^^^^^^^^^^^^^^^^^^^^^^^^^^^^^^^^^
  File "/home/airflow/.local/lib/python3.11/site-packages/pandas/io/parsers/readers.py", line 1448, in __init__
    self._engine = self._make_engine(f, self.engine)
                   ^^^^^^^^^^^^^^^^^^^^^^^^^^^^^^^^^
  File "/home/airflow/.local/lib/python3.11/site-packages/pandas/io/parsers/readers.py", line 1705, in _make_engine
    self.handles = get_handle(
                   ^^^^^^^^^^^
  File "/home/airflow/.local/lib/python3.11/site-packages/pandas/io/common.py", line 863, in get_handle
    handle = open(
             ^^^^^
FileNotFoundError: [Errno 2] No such file or directory: '/app/data/input.csv'
[2025-06-22T15:40:38.492+0000] {taskinstance.py:1206} INFO - Marking task as FAILED. dag_id=etl_pipeline, task_id=extract, run_id=scheduled__2025-06-21T00:00:00+00:00, execution_date=20250621T000000, start_date=20250622T154038, end_date=20250622T154038
[2025-06-22T15:40:38.501+0000] {standard_task_runner.py:110} ERROR - Failed to execute job 13 for task extract ([Errno 2] No such file or directory: '/app/data/input.csv'; 226)
[2025-06-22T15:40:38.545+0000] {local_task_job_runner.py:240} INFO - Task exited with return code 1
[2025-06-22T15:40:38.563+0000] {taskinstance.py:3498} INFO - 0 downstream tasks scheduled from follow-on schedule check
[2025-06-22T15:40:38.567+0000] {local_task_job_runner.py:222} INFO - ::endgroup::
[2025-06-22T15:50:47.015+0000] {local_task_job_runner.py:120} INFO - ::group::Pre task execution logs
[2025-06-22T15:50:47.117+0000] {taskinstance.py:2076} INFO - Dependencies all met for dep_context=non-requeueable deps ti=<TaskInstance: etl_pipeline.extract scheduled__2025-06-21T00:00:00+00:00 [queued]>
[2025-06-22T15:50:47.123+0000] {taskinstance.py:2076} INFO - Dependencies all met for dep_context=requeueable deps ti=<TaskInstance: etl_pipeline.extract scheduled__2025-06-21T00:00:00+00:00 [queued]>
[2025-06-22T15:50:47.123+0000] {taskinstance.py:2306} INFO - Starting attempt 2 of 2
[2025-06-22T15:50:47.133+0000] {taskinstance.py:2330} INFO - Executing <Task(_PythonDecoratedOperator): extract> on 2025-06-21 00:00:00+00:00
[2025-06-22T15:50:47.139+0000] {standard_task_runner.py:63} INFO - Started process 322 to run task
[2025-06-22T15:50:47.142+0000] {standard_task_runner.py:90} INFO - Running: ['airflow', 'tasks', 'run', 'etl_pipeline', 'extract', 'scheduled__2025-06-21T00:00:00+00:00', '--job-id', '20', '--raw', '--subdir', 'DAGS_FOLDER/etl_dag.py', '--cfg-path', '/tmp/tmptjcely3p']
[2025-06-22T15:50:47.144+0000] {standard_task_runner.py:91} INFO - Job 20: Subtask extract
[2025-06-22T15:50:47.187+0000] {task_command.py:426} INFO - Running <TaskInstance: etl_pipeline.extract scheduled__2025-06-21T00:00:00+00:00 [running]> on host ecff408c7856
[2025-06-22T15:50:47.252+0000] {taskinstance.py:2648} INFO - Exporting env vars: AIRFLOW_CTX_DAG_OWNER='airflow' AIRFLOW_CTX_DAG_ID='etl_pipeline' AIRFLOW_CTX_TASK_ID='extract' AIRFLOW_CTX_EXECUTION_DATE='2025-06-21T00:00:00+00:00' AIRFLOW_CTX_TRY_NUMBER='2' AIRFLOW_CTX_DAG_RUN_ID='scheduled__2025-06-21T00:00:00+00:00'
[2025-06-22T15:50:47.253+0000] {taskinstance.py:430} INFO - ::endgroup::
[2025-06-22T15:50:47.255+0000] {taskinstance.py:441} INFO - ::group::Post task execution logs
[2025-06-22T15:50:47.255+0000] {taskinstance.py:2905} ERROR - Task failed with exception
Traceback (most recent call last):
  File "/home/airflow/.local/lib/python3.11/site-packages/airflow/models/taskinstance.py", line 465, in _execute_task
    result = _execute_callable(context=context, **execute_callable_kwargs)
             ^^^^^^^^^^^^^^^^^^^^^^^^^^^^^^^^^^^^^^^^^^^^^^^^^^^^^^^^^^^^^
  File "/home/airflow/.local/lib/python3.11/site-packages/airflow/models/taskinstance.py", line 432, in _execute_callable
    return execute_callable(context=context, **execute_callable_kwargs)
           ^^^^^^^^^^^^^^^^^^^^^^^^^^^^^^^^^^^^^^^^^^^^^^^^^^^^^^^^^^^^
  File "/home/airflow/.local/lib/python3.11/site-packages/airflow/models/baseoperator.py", line 400, in wrapper
    return func(self, *args, **kwargs)
           ^^^^^^^^^^^^^^^^^^^^^^^^^^^
  File "/home/airflow/.local/lib/python3.11/site-packages/airflow/decorators/base.py", line 265, in execute
    return_value = super().execute(context)
                   ^^^^^^^^^^^^^^^^^^^^^^^^
  File "/home/airflow/.local/lib/python3.11/site-packages/airflow/models/baseoperator.py", line 400, in wrapper
    return func(self, *args, **kwargs)
           ^^^^^^^^^^^^^^^^^^^^^^^^^^^
  File "/home/airflow/.local/lib/python3.11/site-packages/airflow/operators/python.py", line 235, in execute
    return_value = self.execute_callable()
                   ^^^^^^^^^^^^^^^^^^^^^^^
  File "/home/airflow/.local/lib/python3.11/site-packages/airflow/operators/python.py", line 252, in execute_callable
    return self.python_callable(*self.op_args, **self.op_kwargs)
           ^^^^^^^^^^^^^^^^^^^^^^^^^^^^^^^^^^^^^^^^^^^^^^^^^^^^^
  File "/opt/airflow/dags/etl_dag.py", line 25, in extract
    return _extract().to_dict(orient="records")
           ^^^^^^^^^^
  File "/opt/airflow/app/pipeline.py", line 19, in extract
    return pd.read_csv(CSV_PATH)
           ^^^^^^^^^^^^^^^^^^^^^
  File "/home/airflow/.local/lib/python3.11/site-packages/pandas/io/parsers/readers.py", line 948, in read_csv
    return _read(filepath_or_buffer, kwds)
           ^^^^^^^^^^^^^^^^^^^^^^^^^^^^^^^
  File "/home/airflow/.local/lib/python3.11/site-packages/pandas/io/parsers/readers.py", line 611, in _read
    parser = TextFileReader(filepath_or_buffer, **kwds)
             ^^^^^^^^^^^^^^^^^^^^^^^^^^^^^^^^^^^^^^^^^^
  File "/home/airflow/.local/lib/python3.11/site-packages/pandas/io/parsers/readers.py", line 1448, in __init__
    self._engine = self._make_engine(f, self.engine)
                   ^^^^^^^^^^^^^^^^^^^^^^^^^^^^^^^^^
  File "/home/airflow/.local/lib/python3.11/site-packages/pandas/io/parsers/readers.py", line 1705, in _make_engine
    self.handles = get_handle(
                   ^^^^^^^^^^^
  File "/home/airflow/.local/lib/python3.11/site-packages/pandas/io/common.py", line 863, in get_handle
    handle = open(
             ^^^^^
FileNotFoundError: [Errno 2] No such file or directory: '/app/data/input.csv'
[2025-06-22T15:50:47.264+0000] {taskinstance.py:1206} INFO - Marking task as FAILED. dag_id=etl_pipeline, task_id=extract, run_id=scheduled__2025-06-21T00:00:00+00:00, execution_date=20250621T000000, start_date=20250622T155047, end_date=20250622T155047
[2025-06-22T15:50:47.272+0000] {standard_task_runner.py:110} ERROR - Failed to execute job 20 for task extract ([Errno 2] No such file or directory: '/app/data/input.csv'; 322)
[2025-06-22T15:50:47.285+0000] {local_task_job_runner.py:240} INFO - Task exited with return code 1
[2025-06-22T15:50:47.304+0000] {taskinstance.py:3498} INFO - 0 downstream tasks scheduled from follow-on schedule check
[2025-06-22T15:50:47.308+0000] {local_task_job_runner.py:222} INFO - ::endgroup::
